<?xml version="1.0" ?>
<robot name="panda">
  <!-- Base del robot -->
  <link name="base_link">
    <visual>
      <origin xyz="0 0 0.025" rpy="0 0 0"/>
      <geometry>
        <box size="0.32 0.26 0.2"/>
      </geometry>
      <material name="Cyan1">
        <color rgba="0 0.9 0.9 1.0"/>
      </material>
    </visual>
  </link>

  <!-- Rueda izquierda -->
  <link name="left_wheel">
    <visual>
      <origin xyz="0 0.13 0.0425" rpy="0 1.5708 1.5708"/>
      <geometry>
        <cylinder radius="0.07" length="0.02"/>
      </geometry>
      <material name="Black">
        <color rgba="0 0 0 1"/>
      </material>
    </visual>
  </link>

  <!-- Rueda derecha -->
  <link name="right_wheel">
    <visual>
      <origin xyz="0 -0.13 0.0425" rpy="0 1.5708 -1.5708"/>
      <geometry>
        <cylinder radius="0.05" length="0.02"/>
      </geometry>
      <material name="Black">
        <color rgba="0 0 0 1"/>
      </material>
    </visual>
  </link>

  <!-- Joint para la rueda izquierda -->
  <joint name="left_wheel_joint" type="continuous">
    <parent link="base_link"/>
    <child link="left_wheel"/>
    <origin xyz="0 0 0.0425" rpy="0 0 0"/>
    <axis xyz="0 0 1"/>
  </joint>

  <!-- Joint para la rueda derecha -->
  <joint name="right_wheel_joint" type="continuous">
    <parent link="base_link"/>
    <child link="right_wheel"/>
    <origin xyz="0 0 0.0425" rpy="0 0 0"/>
    <axis xyz="0 0 1"/>
  </joint>
</robot>
