<?xml version="1.0" ?>
<robot name="ejercicio3">
urdf_   
	<!-- * * * BASE DEL ROBOT * * * -->
 	<link name="base_link">
		<visual>
		    <origin xyz="0 0 0.1" rpy="0 0 0"/>
			<geometry>
				<box size="0.35 0.35 0.075"/>
			</geometry>
			<material name="Cyan1">
	       		<color rgba="0 0.9 0.9 1.0"/>
	     	</material>
		</visual>	
	</link>

	<!-- * * BASE DE LA PIERNA * * * -->
 	<link name="first_leg_art">
		<visual>
		    <origin xyz="0 0 0" rpy="0 0 0"/>
			<geometry>
				<cylinder radius="0.045" length="0.01"/>
			</geometry>
			<material name="Green">
	       		<color rgba="0 1 0 1.0"/>
	     	</material>
		</visual>	
	</link>

 	<link name="first_leg_base">
		<visual>
		    <origin xyz="0 0 0" rpy="0 0 0"/>
			<geometry>
				<box size="0.075 0.15 0.01"/>
			</geometry>
			<material name="Red">
	       		<color rgba="1 0 0 1.0"/>
	     	</material>
		</visual>	
	</link>

	<!-- * * PRIMERA ARTICULACION * * * -->	
 	<link name="first_leg_medium">
		<visual>
		    <origin xyz="0 0 0" rpy="0 0 0"/>
			<geometry>
				<box size="0.055 0.025 0.055"/>
			</geometry>
			<material name="Blue">
	       		<color rgba="0 0 1 1.0"/>
	     	</material>
		</visual>	
	</link>

	<link name="first_leg_medium_art">
		<visual>
		    <origin xyz="0 0 0" rpy="0 0 0"/>
			<geometry>
				<box size="0.025 0.025 0.15"/>
			</geometry>
			<material name="black">
	       		<color rgba="0 0 0 1.0"/>
	     	</material>
		</visual>	
	</link>

	<link name="first_leg_medium_circle">
		<visual>
		    <origin xyz="0 0 0" rpy="0 0 0"/>
			<geometry>
				<cylinder radius="0.015" length="0.005"/>
			</geometry>
			<material name="Green">
	       		<color rgba="0 1 0 1.0"/>
	     	</material>
		</visual>	
	</link>

	<!-- * * SEGUNDA ARTICULACION * * * -->	
	<link name="first_leg_top_circle">
		<visual>
		    <origin xyz="0 0 0" rpy="0 0 0"/>
			<geometry>
				<cylinder radius="0.015" length="0.005"/>
			</geometry>
			<material name="Green">
	       		<color rgba="0 1 0 1.0"/>
	     	</material>
		</visual>	
	</link>

	<link name="first_leg_top_art">
		<visual>
		    <origin xyz="0 0 0" rpy="0 0 0"/>
			<geometry>
				<box size="0.025 0.025 0.225"/>
			</geometry>
			<material name="black">
	       		<color rgba="0 0 0 1.0"/>
	     	</material>
		</visual>	
	</link>

	<!-- * * * JUNTAS * * * -->

 	<!-- * * * LA BASE CON LA ARTICULACIÓN * * * -->

	<joint name="art_base_joint" type="revolute">
    	<parent link="base_link"/>
    	<child link="first_leg_art"/>
    	<origin xyz="0 0.115 0.055" rpy="0 0 0"/>
      	<axis xyz="0 0 1"/>
        <!-- un octavo de pi para el giro de las piernas -->
        <limit lower="-0.3916" upper="0.3916" effort="10" velocity="3"/>
	</joint>

	<!-- Articulaciones de las piernas -->

	<joint name="art_base_leg_joint" type="fixed">
    	<parent link="first_leg_art"/>
    	<child link="first_leg_base"/>
    	<origin xyz="0 0.05 -0.01" rpy="0 0 0"/>
        <limit lower="-3.1416" upper="3.1416" effort="10" velocity="3"/>
	</joint>

 	<!-- * * * BASE DE LA PRIMERA ARTICULACION * * * -->

	<joint name="medium_base_joint_fixed" type="fixed">
    	<parent link="first_leg_base"/>
    	<child link="first_leg_medium"/>
    	<origin xyz="0 0.05 0.0252" rpy="0 0 0"/>
	</joint>

	<joint name="medium_base_joint" type="revolute">
    	<parent link="first_leg_medium"/>
    	<child link="first_leg_medium_circle"/>
    	<origin xyz="0.03 0 0.02" rpy="0 1.5708 0"/>
      	<axis xyz="0 0 1"/>
        <limit lower="-0.6283" upper="0.1" effort="10" velocity="3"/>
	</joint>

	<joint name="medium_base_art_joint" type="fixed">
    	<parent link="first_leg_medium_circle"/>
    	<child link="first_leg_medium_art"/>
    	<origin xyz="-0.07 0 0.015" rpy="0 1.5708 0"/>
	</joint>

 	<!-- * * * BASE DE LA SEGUNDA ARTICULACIÓN * * * -->

	<joint name="top_medium_circle_joint" type="revolute">
    	<parent link="first_leg_medium_art"/>
    	<child link="first_leg_top_circle"/>
    	<origin xyz="0.015 0 -0.055" rpy="0 1.5708 0"/>
      	<axis xyz="0 0 1"/>
        <limit lower="1.5708" upper="3.1416" effort="10" velocity="3"/>
	</joint>

	<joint name="top_medium_art_joint" type="fixed">
    	<parent link="first_leg_top_circle"/>
    	<child link="first_leg_top_art"/>
    	<origin xyz="0.1 0 0.015" rpy="0 1.5708 0"/>
	</joint>

	<!-- SEGUNDA PIERNA -->
 	<link name="second_leg_art">
		<visual>
		    <origin xyz="0 0 0" rpy="0 0 0"/>
			<geometry>
				<cylinder radius="0.045" length="0.01"/>
			</geometry>
			<material name="Green">
	       		<color rgba="0 1 0 1.0"/>
	     	</material>
		</visual>	
	</link>

 	<link name="second_leg_base">
		<visual>
		    <origin xyz="0 0 0" rpy="0 0 0"/>
			<geometry>
				<box size="0.075 0.15 0.01"/>
			</geometry>
			<material name="Red">
	       		<color rgba="1 0 0 1.0"/>
	     	</material>
		</visual>	
	</link>

	<!-- * * PRIMERA ARTICULACION SEGUNDA PIERNA* * * -->	
 	<link name="second_leg_medium">
		<visual>
		    <origin xyz="0 0 0" rpy="0 0 0"/>
			<geometry>
				<box size="0.055 0.025 0.055"/>
			</geometry>
			<material name="Blue">
	       		<color rgba="0 0 1 1.0"/>
	     	</material>
		</visual>	
	</link>

	<link name="second_leg_medium_art">
		<visual>
		    <origin xyz="0 0 0" rpy="0 0 0"/>
			<geometry>
				<box size="0.025 0.025 0.15"/>
			</geometry>
			<material name="black">
	       		<color rgba="0 0 0 1.0"/>
	     	</material>
		</visual>	
	</link>

	<link name="second_leg_medium_circle">
		<visual>
		    <origin xyz="0 0 0" rpy="0 0 0"/>
			<geometry>
				<cylinder radius="0.015" length="0.005"/>
			</geometry>
			<material name="Green">
	       		<color rgba="0 1 0 1.0"/>
	     	</material>
		</visual>	
	</link>

	<!-- * * SEGUNDA ARTICULACION SEGUNDA PIERNA* * * -->	
	<link name="second_leg_top_circle">
		<visual>
		    <origin xyz="0 0 0" rpy="0 0 0"/>
			<geometry>
				<cylinder radius="0.015" length="0.005"/>
			</geometry>
			<material name="Green">
	       		<color rgba="0 1 0 1.0"/>
	     	</material>
		</visual>	
	</link>

	<link name="second_leg_top_art">
		<visual>
		    <origin xyz="0 0 0" rpy="0 0 0"/>
			<geometry>
				<box size="0.025 0.025 0.225"/>
			</geometry>
			<material name="black">
	       		<color rgba="0 0 0 1.0"/>
	     	</material>
		</visual>	
	</link>

	 	<!-- * * * LA BASE CON LA ARTICULACIÓN * * * -->
	<joint name="second_art_base_joint" type="revolute">
    	<parent link="base_link"/>
    	<child link="second_leg_art"/>
    	<origin xyz="0 -0.115 0.055" rpy="0 0 0"/>
      	<axis xyz="0 0 1"/>
        <limit lower="-0.3916" upper="0.3916" effort="10" velocity="3"/>
	</joint>
		<!-- Articulaciones de las piernas -->
	<joint name="second_art_leg_joint" type="fixed">
    	<parent link="second_leg_art"/>
    	<child link="second_leg_base"/>
    	<origin xyz="0 -0.05 -0.01" rpy="0 0 0"/>
	</joint>
 	<!-- * * * BASE DE LA PRIMERA ARTICULACION * * * -->
	<joint name="second_medium_base_joint_fixed" type="fixed">
    	<parent link="second_leg_base"/>
    	<child link="second_leg_medium"/>
    	<origin xyz="0 -0.05 0.0252" rpy="0 0 0"/>
	</joint>

	<joint name="second_medium_base_joint" type="revolute">
    	<parent link="second_leg_medium"/>
    	<child link="second_leg_medium_circle"/>
    	<origin xyz="0.03 0 0.02" rpy="0 1.5708 0"/>
      	<axis xyz="0 0 1"/>
        <limit lower="-0.1" upper="0.3916" effort="10" velocity="3"/>
	</joint>

	<joint name="second_medium_base_art_joint" type="fixed">
    	<parent link="second_leg_medium_circle"/>
    	<child link="second_leg_medium_art"/>
    	<origin xyz="-0.07 0 0.015" rpy="0 1.5708 0"/>
	</joint>

 	<!-- * * * BASE DE LA SEGUNDA ARTICULACIÓN SEGUNDA PIERNA * * * -->

	<joint name="second_top_medium_circle_joint" type="revolute">
    	<parent link="second_leg_medium_art"/>
    	<child link="second_leg_top_circle"/>
    	<origin xyz="-0.015 0 -0.055" rpy="0 1.5708 0"/>
      	<axis xyz="0 0 1"/>
        <limit lower="-3.1416" upper="-1.5708" effort="10" velocity="3"/>
	</joint>

	<joint name="second_top_medium_art_joint" type="fixed">
    	<parent link="second_leg_top_circle"/>
    	<child link="second_leg_top_art"/>
    	<origin xyz="0.1 0 -0.015" rpy="0 1.5708 0"/>
	</joint>

		<!-- ARTICULACIÓN 3 Y 4 -->
	<!-- * * BASE DE LA TERCERA PIERNA * * * -->
 	<link name="third_leg_art">
		<visual>
		    <origin xyz="0 0 0" rpy="0 0 0"/>
			<geometry>
				<cylinder radius="0.045" length="0.01"/>
			</geometry>
			<material name="Green">
	       		<color rgba="0 1 0 1.0"/>
	     	</material>
		</visual>	
	</link>

 	<link name="third_leg_base">
		<visual>
		    <origin xyz="0 0 0" rpy="0 0 0"/>
			<geometry>
				<box size="0.15 0.075 0.01"/>
			</geometry>
			<material name="Red">
	       		<color rgba="1 0 0 1.0"/>
	     	</material>
		</visual>	
	</link>

	<!-- * * PRIMERA ARTICULACION * * * -->	
 	<link name="third_leg_medium">
		<visual>
		    <origin xyz="0 0 0" rpy="0 0 0"/>
			<geometry>
				<box size="0.025 0.055 0.055"/>
			</geometry>
			<material name="Blue">
	       		<color rgba="0 0 1 1.0"/>
	     	</material>
		</visual>	
	</link>

	<link name="third_leg_medium_art">
		<visual>
		    <origin xyz="0 0 0" rpy="0 0 0"/>
			<geometry>
				<box size="0.025 0.025 0.15"/>
			</geometry>
			<material name="black">
	       		<color rgba="0 0 0 1.0"/>
	     	</material>
		</visual>	
	</link>

	<link name="third_leg_medium_circle">
		<visual>
		    <origin xyz="0 0 0" rpy="0 0 0"/>
			<geometry>
				<cylinder radius="0.015" length="0.005"/>
			</geometry>
			<material name="Green">
	       		<color rgba="0 1 0 1.0"/>
	     	</material>
		</visual>	
	</link>

	<!-- * * SEGUNDA ARTICULACION * * * -->	
	<link name="third_leg_top_circle">
		<visual>
		    <origin xyz="0 0 0" rpy="0 0 0"/>
			<geometry>
				<cylinder radius="0.015" length="0.005"/>
			</geometry>
			<material name="Green">
	       		<color rgba="0 1 0 1.0"/>
	     	</material>
		</visual>	
	</link>

	<link name="third_leg_top_art">
		<visual>
		    <origin xyz="0 0 0" rpy="0 0 0"/>
			<geometry>
				<box size="0.025 0.025 0.225"/>
			</geometry>
			<material name="black">
	       		<color rgba="0 0 0 1.0"/>
	     	</material>
		</visual>	
	</link>

	<!-- * * * JUNTAS * * * -->
 	<!-- * * * LA BASE CON LA ARTICULACIÓN * * * -->
	<joint name="third_art_base_joint" type="revolute">
    	<parent link="base_link"/>
    	<child link="third_leg_art"/>
    	<origin xyz="0.115 0 0.055" rpy="0 0 0"/>
      	<axis xyz="0 0 1"/>
        <limit lower="-0.3916" upper="0.3916" effort="10" velocity="3"/>
	</joint>
	<!-- Articulaciones de las piernas -->
	<joint name="third_art_base_leg_joint" type="fixed">
    	<parent link="third_leg_art"/>
    	<child link="third_leg_base"/>
    	<origin xyz="0.05 0 -0.01" rpy="0 0 0"/>
	</joint>
 	<!-- * * * BASE DE LA PRIMERA ARTICULACION * * * -->
	<joint name="third_medium_base_joint_fixed" type="fixed">
    	<parent link="third_leg_base"/>
    	<child link="third_leg_medium"/>
    	<origin xyz="0.05 0 0.0252" rpy="0 0 0"/>
	</joint>

	<joint name="third_medium_base_joint" type="revolute">
    	<parent link="third_leg_medium"/>
    	<child link="third_leg_medium_circle"/>
    	<origin xyz="0 0.03 0.02" rpy="1.5708 0 0"/>
      	<axis xyz="0 0 1"/>
        <limit lower="-0.6283" upper="0.1" effort="10" velocity="3"/>
	</joint>

	<joint name="third_medium_base_art_joint" type="fixed">
    	<parent link="third_leg_medium_circle"/>
    	<child link="third_leg_medium_art"/>
    	<origin xyz="0 0.07 -0.015" rpy="1.5708 0 0"/>
	</joint>
 	<!-- * * * BASE DE LA SEGUNDA ARTICULACIÓN * * * -->
	<joint name="third_top_medium_circle_joint" type="revolute">
    	<parent link="third_leg_medium_art"/>
    	<child link="third_leg_top_circle"/>
    	<origin xyz="0 0.015 -0.055" rpy="1.5708 0 0"/>
      	<axis xyz="0 0 1"/>
        <limit lower="1.5708" upper="3.1416" effort="10" velocity="3"/>
	</joint>

	<joint name="third_top_medium_art_joint" type="fixed">
    	<parent link="third_leg_top_circle"/>
    	<child link="third_leg_top_art"/>
    	<origin xyz="0 -0.1 -0.015" rpy="1.5708 0 0"/>
	</joint>

	<!-- * * BASE DE LA CUARTA PIERNA * * * -->
 	<link name="fourth_leg_art">
		<visual>
		    <origin xyz="0 0 0" rpy="0 0 0"/>
			<geometry>
				<cylinder radius="0.045" length="0.01"/>
			</geometry>
			<material name="Green">
	       		<color rgba="0 1 0 1.0"/>
	     	</material>
		</visual>	
	</link>

 	<link name="fourth_leg_base">
		<visual>
		    <origin xyz="0 0 0" rpy="0 0 0"/>
			<geometry>
				<box size="0.15 0.075 0.01"/>
			</geometry>
			<material name="Red">
	       		<color rgba="1 0 0 1.0"/>
	     	</material>
		</visual>	
	</link>

	<!-- * * PRIMERA ARTICULACION * * * -->	
 	<link name="fourth_leg_medium">
		<visual>
		    <origin xyz="0 0 0" rpy="0 0 0"/>
			<geometry>
				<box size="0.025 0.055 0.055"/>
			</geometry>
			<material name="Blue">
	       		<color rgba="0 0 1 1"/>
	     	</material>
		</visual>	
	</link>

	<link name="fourth_leg_medium_art">
		<visual>
		    <origin xyz="0 0 0" rpy="0 0 0"/>
			<geometry>
				<box size="0.025 0.025 0.15"/>
			</geometry>
			<material name="black">
	       		<color rgba="0 0 0 1.0"/>
	     	</material>
		</visual>	
	</link>

	<link name="fourth_leg_medium_circle">
		<visual>
		    <origin xyz="0 0 0" rpy="0 0 0"/>
			<geometry>
				<cylinder radius="0.015" length="0.005"/>
			</geometry>
			<material name="Green">
	       		<color rgba="0 1 0 1.0"/>
	     	</material>
		</visual>	
	</link>

	<!-- * * SEGUNDA ARTICULACION * * * -->	
	<link name="fourth_leg_top_circle">
		<visual>
		    <origin xyz="0 0 0" rpy="0 0 0"/>
			<geometry>
				<cylinder radius="0.015" length="0.005"/>
			</geometry>
			<material name="Green">
	       		<color rgba="0 1 0 1.0"/>
	     	</material>
		</visual>	
	</link>

	<link name="fourth_leg_top_art">
		<visual>
		    <origin xyz="0 0 0" rpy="0 0 0"/>
			<geometry>
				<box size="0.025 0.025 0.225"/>
			</geometry>
			<material name="black">
	       		<color rgba="0 0 0 1.0"/>
	     	</material>
		</visual>	
	</link>

	<!-- * * * JUNTAS * * * -->
 	<!-- * * * LA BASE CON LA ARTICULACIÓN * * * -->
	<joint name="fourth_art_base_joint" type="revolute">
    	<parent link="base_link"/>
    	<child link="fourth_leg_art"/>
    	<origin xyz="-0.115 0 0.055" rpy="0 0 0"/>
      	<axis xyz="0 0 1"/>
        <limit lower="-0.3916" upper="0.3916" effort="10" velocity="3"/>
	</joint>
	<!-- Articulaciones de las piernas -->
	<joint name="fourth_art_base_leg_joint" type="fixed">
    	<parent link="fourth_leg_art"/>
    	<child link="fourth_leg_base"/>
    	<origin xyz="-0.05 0 -0.01" rpy="0 0 0"/>
	</joint>
 	<!-- * * * BASE DE LA PRIMERA ARTICULACION * * * -->
	<joint name="fourth_medium_base_joint_fixed" type="fixed">
    	<parent link="fourth_leg_base"/>
    	<child link="fourth_leg_medium"/>
    	<origin xyz="-0.05 0 0.0252" rpy="0 0 0"/>
	</joint>

	<joint name="fourth_medium_base_joint" type="revolute">
    	<parent link="fourth_leg_medium"/>
    	<child link="fourth_leg_medium_circle"/>
    	<origin xyz="0 -0.03 0.02" rpy="1.5708 0 0"/>
      	<axis xyz="0 0 1"/>
        <limit lower="-0.1" upper="0.3916" effort="10" velocity="3"/>
	</joint>

	<joint name="fourth_medium_base_art_joint" type="fixed">
    	<parent link="fourth_leg_medium_circle"/>
    	<child link="fourth_leg_medium_art"/>
    	<origin xyz="0 0.07 0.015" rpy="1.5708 0 0"/>
	</joint>
	<!-- * * * BASE DE LA SEGUNDA ARTICULACIÓN * * * -->
	<joint name="fourth_top_medium_circle_joint" type="revolute">
    	<parent link="fourth_leg_medium_art"/>
    	<child link="fourth_leg_top_circle"/>
    	<origin xyz="0 -0.015 -0.055" rpy="1.5708 0 0"/>
      	<axis xyz="0 0 1"/>
        <limit lower="-3.1416" upper="-1.5708" effort="10" velocity="3"/>
	</joint>

	<joint name="fourth_top_medium_art_joint" type="fixed">
    	<parent link="fourth_leg_top_circle"/>
    	<child link="fourth_leg_top_art"/>
    	<origin xyz="0 -0.1 0.015" rpy="1.5708 0 0"/>
	</joint>
 	
</robot>